<robot name="unnamed" version="1.0">
  <joint name="00_base_b_link_joint" type="fixed">
    <origin rpy="-0.00000 1.57080 0.00000" xyz="0.00000 0.70000 0.55000"/>
    <parent link="base_link"/>
    <child link="base_b_link"/>
  </joint>
  <joint name="01_Cilindro_verti_1_link_joint" type="fixed">
    <origin rpy="0.00000 -1.57080 0.00000" xyz="-0.55000 -0.00000 0.00000"/>
    <parent link="base_b_link"/>
    <child link="Cilindro_verti_1_link"/>
  </joint>
  <joint name="02_Cilindro_link_joint" type="revolute">
    <limit lower="-6.28000" upper="6.28000" effort="25.00000" velocity="0.00000"/>
    <origin rpy="0.00000 0.00000 0.00000" xyz="0.00000 -0.00000 0.60000"/>
    <parent link="Cilindro_verti_1_link"/>
    <child link="Cilindro_link"/>
    <axis xyz="0.00000 0.00000 1.00000"/>
  </joint>
  <joint name="03_horizontal1_link_joint" type="fixed">
    <origin rpy="0.00000 0.00000 0.00000" xyz="-0.00000 0.50000 0.00000"/>
    <parent link="Cilindro_link"/>
    <child link="horizontal1_link"/>
  </joint>
  <joint name="04_Cilindro_verti_3_link_joint" type="revolute">
    <limit lower="-2.15000" upper="2.15000" effort="25.00000" velocity="0.00000"/>
    <origin rpy="0.00000 0.00000 0.00000" xyz="0.00000 0.50000 0.10000"/>
    <parent link="horizontal1_link"/>
    <child link="Cilindro_verti_3_link"/>
    <axis xyz="0.00000 0.00000 1.00000"/>
  </joint>
  <joint name="05_horizontal2_link_joint" type="fixed">
    <origin rpy="0.00000 0.00000 0.00000" xyz="-0.00000 0.50000 0.10000"/>
    <parent link="Cilindro_verti_3_link"/>
    <child link="horizontal2_link"/>
  </joint>
  <joint name="06_Cilindro_verti_4_link_joint" type="fixed">
    <origin rpy="0.00000 0.00000 0.00000" xyz="0.00000 0.50000 0.10000"/>
    <parent link="horizontal2_link"/>
    <child link="Cilindro_verti_4_link"/>
  </joint>
  <joint name="07_Cilindro_verti_5_link_joint" type="prismatic">
    <limit lower="-2.00000" upper="2.50000" effort="25.00000" velocity="0.00000"/>
    <origin rpy="0.00000 0.00000 0.00000" xyz="0.00000 -0.01000 -1.00000"/>
    <parent link="Cilindro_verti_4_link"/>
    <child link="Cilindro_verti_5_link"/>
    <axis xyz="0.00000 0.00000 1.00000"/>
  </joint>
  <joint name="08_grip_link_joint" type="revolute">
    <limit lower="-1.57000" upper="1.57000" effort="25.00000" velocity="5.00000"/>
    <origin rpy="0.00000 0.00000 0.00000" xyz="-0.00000 0.01000 -1.50000"/>
    <parent link="Cilindro_verti_5_link"/>
    <child link="grip_link"/>
    <axis xyz="0.00000 0.00000 1.00000"/>
  </joint>
  <joint name="09_grip_d_link_joint" type="prismatic">
    <limit lower="-0.11000" upper="0.00000" effort="25.00000" velocity="5.00000"/>
    <origin rpy="0.00000 1.57080 0.00000" xyz="0.40000 0.00000 -0.30000"/>
    <parent link="grip_link"/>
    <child link="grip_d_link"/>
    <axis xyz="0.00000 0.00000 1.00000"/>
  </joint>
  <joint name="09_grip_i_link_joint" type="prismatic">
    <limit lower="-0.11000" upper="0.00000" effort="25.00000" velocity="0.00000"/>
    <origin rpy="0.00000 -1.57080 0.00000" xyz="-0.40000 0.00000 -0.30000"/>
    <parent link="grip_link"/>
    <child link="grip_i_link"/>
    <axis xyz="0.00000 0.00000 1.00000"/>
  </joint>
  <joint name="Camara_frontal_link_joint" type="fixed">
    <origin rpy="0.00000 0.00000 0.00000" xyz="0.00000 1.35000 0.50000"/>
    <parent link="base_link"/>
    <child link="Camara_frontal_link"/>
  </joint>
  <joint name="Camara_grip_link_joint" type="fixed">
    <origin rpy="0.00000 0.00000 0.00000" xyz="0.00000 2.70000 -0.55000"/>
    <parent link="base_link"/>
    <child link="Camara_grip_link"/>
  </joint>
  <joint name="Cilindro_D1_link_joint" type="fixed">
    <origin rpy="1.57080 0.78540 -1.57080" xyz="0.25000 0.03536 -0.60104"/>
    <parent link="Cubo_d1_link"/>
    <child link="Cilindro_D1_link"/>
  </joint>
  <joint name="Cilindro_D2_link_joint" type="fixed">
    <origin rpy="1.57080 0.00000 -1.57080" xyz="0.25000 0.00000 -0.55000"/>
    <parent link="Cubo_d2_link"/>
    <child link="Cilindro_D2_link"/>
  </joint>
  <joint name="Cilindro_D3_link_joint" type="fixed">
    <origin rpy="1.57080 -0.78540 -1.57080" xyz="0.25000 -0.03536 -0.60104"/>
    <parent link="Cubo_d3_link"/>
    <child link="Cilindro_D3_link"/>
  </joint>
  <joint name="Cilindro_i1_link_joint" type="fixed">
    <origin rpy="1.57080 -0.78540 1.57080" xyz="-0.25000 0.03536 -0.60104"/>
    <parent link="Cubo_i1_link"/>
    <child link="Cilindro_i1_link"/>
  </joint>
  <joint name="Cilindro_i2_link_joint" type="fixed">
    <origin rpy="1.57080 -0.00000 1.57080" xyz="-0.25000 0.00000 -0.55000"/>
    <parent link="Cubo_i3_link"/>
    <child link="Cilindro_i2_link"/>
  </joint>
  <joint name="Cilindro_i3_link_joint" type="fixed">
    <origin rpy="1.57080 0.78540 1.57080" xyz="-0.25000 -0.03536 -0.60104"/>
    <parent link="Cubo_i2_link"/>
    <child link="Cilindro_i3_link"/>
  </joint>
  <joint name="Cubo_d1_link_joint" type="fixed">
    <origin rpy="-0.78540 0.00000 0.00000" xyz="0.50000 -0.80000 -0.80000"/>
    <parent link="base_link"/>
    <child link="Cubo_d1_link"/>
  </joint>
  <joint name="Cubo_d2_link_joint" type="fixed">
    <origin rpy="0.78540 0.00000 0.00000" xyz="0.50000 0.80000 -0.80000"/>
    <parent link="base_link"/>
    <child link="Cubo_d3_link"/>
  </joint>
  <joint name="Cubo_d3_link_joint" type="fixed">
    <origin rpy="0.00000 0.00000 0.00000" xyz="0.50000 0.00000 -0.70000"/>
    <parent link="base_link"/>
    <child link="Cubo_d2_link"/>
  </joint>
  <joint name="Cubo_i1_link_joint" type="fixed">
    <origin rpy="-0.78540 0.00000 0.00000" xyz="-0.50000 -0.80000 -0.80000"/>
    <parent link="base_link"/>
    <child link="Cubo_i1_link"/>
  </joint>
  <joint name="Cubo_i2_link_joint" type="fixed">
    <origin rpy="0.78540 0.00000 0.00000" xyz="-0.50000 0.80000 -0.80000"/>
    <parent link="base_link"/>
    <child link="Cubo_i2_link"/>
  </joint>
  <joint name="Cubo_i3_link_joint" type="fixed">
    <origin rpy="0.00000 0.00000 0.00000" xyz="-0.50000 0.00000 -0.70000"/>
    <parent link="base_link"/>
    <child link="Cubo_i3_link"/>
  </joint>
  <joint name="Rueda_D1_link_joint" type="continuous">
    <limit lower="0" upper="0" effort="25.00000" velocity="5.00000"/>
    <origin rpy="3.14159 0.00000 3.14159" xyz="-0.00000 0.00000 -0.05000"/>
    <parent link="Cilindro_D1_link"/>
    <child link="Rueda_D1_link"/>
    <axis xyz="0.00000 0.00000 1.00000"/>
  </joint>
  <joint name="Rueda_D2_link_joint" type="continuous">
    <limit lower="0" upper="0" effort="25.00000" velocity="5.00000"/>
    <origin rpy="3.14159 0.00000 -3.14159" xyz="-0.00000 -0.00000 -0.05000"/>
    <parent link="Cilindro_D2_link"/>
    <child link="Rueda_D2_link"/>
    <axis xyz="0.00000 0.00000 1.00000"/>
  </joint>
  <joint name="Rueda_D3_link_joint" type="continuous">
    <limit lower="0" upper="0" effort="25.00000" velocity="5.00000"/>
    <origin rpy="3.14159 0.00000 3.14159" xyz="0.00000 -0.00000 -0.05000"/>
    <parent link="Cilindro_D3_link"/>
    <child link="Rueda_D3_link"/>
    <axis xyz="0.00000 0.00000 1.00000"/>
  </joint>
  <joint name="Rueda_I1_link_joint" type="continuous">
    <limit lower="0" upper="0" effort="25.00000" velocity="5.00000"/>
    <origin rpy="3.14159 -0.00000 -3.14159" xyz="0.00000 -0.00000 -0.05000"/>
    <parent link="Cilindro_i1_link"/>
    <child link="Rueda_I1_link"/>
    <axis xyz="0.00000 0.00000 1.00000"/>
  </joint>
  <joint name="Rueda_I2_link_joint" type="continuous">
    <limit lower="0" upper="0" effort="25.00000" velocity="5.00000"/>
    <origin rpy="3.14159 -0.00000 -3.14159" xyz="-0.00000 -0.00000 -0.05000"/>
    <parent link="Cilindro_i2_link"/>
    <child link="Rueda_I2_link"/>
    <axis xyz="0.00000 0.00000 1.00000"/>
  </joint>
  <joint name="Rueda_i3_link_joint" type="continuous">
    <limit lower="0" upper="0" effort="25.00000" velocity="5.00000"/>
    <origin rpy="3.14159 -0.00000 -3.14159" xyz="-0.00000 -0.00000 -0.05000"/>
    <parent link="Cilindro_i3_link"/>
    <child link="Rueda_i3_link"/>
    <axis xyz="0.00000 0.00000 1.00000"/>
  </joint>
  <joint name="Sensor_link_joint" type="fixed">
    <origin rpy="0.00000 0.00000 0.00000" xyz="0.00000 0.00000 -0.00000"/>
    <parent link="base_link"/>
    <child link="Sensor_link"/>
  </joint>
  <joint name="base_link_joint" type="fixed">
    <origin rpy="0.00000 0.00000 0.00000" xyz="0.00000 0.00000 0.00000"/>
    <parent link="base_footprint"/>
    <child link="base_link"/>
  </joint>
  <joint name="pared_d_link_joint" type="fixed">
    <origin rpy="0.00000 -1.57080 0.00000" xyz="0.57500 -0.61000 0.75000"/>
    <parent link="base_link"/>
    <child link="pared_d_link"/>
  </joint>
  <joint name="pared_delantera_link_joint" type="fixed">
    <origin rpy="1.57080 -1.57080 0.00000" xyz="0.00000 0.01000 0.75000"/>
    <parent link="base_link"/>
    <child link="pared_delantera_link"/>
  </joint>
  <joint name="pared_i_link_joint" type="fixed">
    <origin rpy="-0.00000 1.57080 0.00000" xyz="-0.57500 -0.61000 0.75000"/>
    <parent link="base_link"/>
    <child link="pared_i_link"/>
  </joint>
  <joint name="pared_trasera_link_joint" type="fixed">
    <origin rpy="-1.57080 1.57080 0.00000" xyz="0.00000 -1.23000 0.75000"/>
    <parent link="base_link"/>
    <child link="pared_trasera_link"/>
  </joint>
  <link name="Camara_frontal_link"/>
  <link name="Camara_grip_link"/>
  <link name="Cilindro_D1_link">
    <collision name="Cilindro_D1_collision">
      <origin rpy="3.14159 -0.00000 -3.14159" xyz="0.00000 0.00000 -0.00000"/>
      <geometry>
        <mesh filename="../meshes/dae/Cilindro.006.dae" scale="0.25000 0.25000 0.27500"/>
      </geometry>
    </collision>
    <inertial>
      <inertia ixx="0.00100" ixy="0.00000" ixz="0.00000" iyy="0.00100" iyz="0.00000" izz="0.00100"/>
      <origin rpy="0.00000 0.00000 0.00000" xyz="0.00000 0.00000 0.00000"/>
      <mass value="2.00000"/>
    </inertial>
    <visual name="Cilindro_D1">
      <origin rpy="3.14159 0.00000 3.14159" xyz="-0.00000 0.00000 0.00000"/>
      <material name="Material.008"/>
      <geometry>
        <mesh filename="../meshes/dae/Cilindro.006.dae" scale="0.25000 0.25000 0.27500"/>
      </geometry>
    </visual>
  </link>
  <link name="Cilindro_D2_link">
    <collision name="Cilindro_D2_collision">
      <origin rpy="3.14159 0.00000 3.14159" xyz="0.00000 -0.00000 0.00000"/>
      <geometry>
        <mesh filename="../meshes/dae/Cilindro.005.dae" scale="0.25000 0.25000 0.27500"/>
      </geometry>
    </collision>
    <inertial>
      <inertia ixx="0.00100" ixy="0.00000" ixz="-0.00000" iyy="0.00100" iyz="0.00000" izz="0.00100"/>
      <origin rpy="0.00000 0.00000 0.00000" xyz="-0.00000 0.00000 0.00000"/>
      <mass value="2.00000"/>
    </inertial>
    <visual name="Cilindro_D2">
      <origin rpy="3.14159 0.00000 -3.14159" xyz="-0.00000 -0.00000 0.00000"/>
      <material name="Material.008"/>
      <geometry>
        <mesh filename="../meshes/dae/Cilindro.005.dae" scale="0.25000 0.25000 0.27500"/>
      </geometry>
    </visual>
  </link>
  <link name="Cilindro_D3_link">
    <collision name="Cilindro_D3_collision">
      <origin rpy="3.14159 -0.00000 -3.14159" xyz="-0.00000 0.00000 -0.00000"/>
      <geometry>
        <mesh filename="../meshes/dae/Cilindro.001.dae" scale="0.25000 0.25000 0.27500"/>
      </geometry>
    </collision>
    <inertial>
      <inertia ixx="0.00100" ixy="0.00000" ixz="0.00000" iyy="0.00100" iyz="0.00000" izz="0.00100"/>
      <origin rpy="0.00000 0.00000 0.00000" xyz="-0.00000 0.00000 0.00000"/>
      <mass value="2.00000"/>
    </inertial>
    <visual name="Cilindro_D3">
      <origin rpy="3.14159 0.00000 3.14159" xyz="-0.00000 0.00000 0.00000"/>
      <material name="Material.008"/>
      <geometry>
        <mesh filename="../meshes/dae/Cilindro.001.dae" scale="0.25000 0.25000 0.27500"/>
      </geometry>
    </visual>
  </link>
  <link name="Cilindro_i1_link">
    <collision name="Cilindro_i1_collision">
      <origin rpy="-0.00000 -0.00000 -0.00000" xyz="-0.00000 -0.00000 -0.00000"/>
      <geometry>
        <mesh filename="../meshes/dae/Cilindro.004.dae" scale="0.25000 0.25000 0.27500"/>
      </geometry>
    </collision>
    <inertial>
      <inertia ixx="0.00100" ixy="-0.00000" ixz="-0.00000" iyy="0.00100" iyz="-0.00000" izz="0.00100"/>
      <origin rpy="0.00000 0.00000 0.00000" xyz="0.00000 0.00000 0.00000"/>
      <mass value="2.00000"/>
    </inertial>
    <visual name="Cilindro_i1">
      <origin rpy="0.00000 0.00000 -0.00000" xyz="-0.00000 0.00000 -0.00000"/>
      <material name="Material.008"/>
      <geometry>
        <mesh filename="../meshes/dae/Cilindro.004.dae" scale="0.25000 0.25000 0.27500"/>
      </geometry>
    </visual>
  </link>
  <link name="Cilindro_i2_link">
    <collision name="Cilindro_i2_collision">
      <origin rpy="0.00000 0.00000 -0.00000" xyz="-0.00000 -0.00000 0.00000"/>
      <geometry>
        <mesh filename="../meshes/dae/Cilindro.002.dae" scale="0.25000 0.25000 0.27500"/>
      </geometry>
    </collision>
    <inertial>
      <inertia ixx="0.00100" ixy="-0.00000" ixz="0.00000" iyy="0.00100" iyz="0.00000" izz="0.00100"/>
      <origin rpy="0.00000 0.00000 0.00000" xyz="-0.00000 0.00000 0.00000"/>
      <mass value="2.00000"/>
    </inertial>
    <visual name="Cilindro_i2">
      <origin rpy="0.00000 0.00000 0.00000" xyz="-0.00000 -0.00000 0.00000"/>
      <material name="Material.008"/>
      <geometry>
        <mesh filename="../meshes/dae/Cilindro.002.dae" scale="0.25000 0.25000 0.27500"/>
      </geometry>
    </visual>
  </link>
  <link name="Cilindro_i3_link">
    <collision name="Cilindro_i3_collision">
      <origin rpy="0.00000 0.00000 0.00000" xyz="0.00000 0.00000 -0.00000"/>
      <geometry>
        <mesh filename="../meshes/dae/Cilindro.003.dae" scale="0.25000 0.25000 0.27500"/>
      </geometry>
    </collision>
    <inertial>
      <inertia ixx="0.00100" ixy="-0.00000" ixz="-0.00000" iyy="0.00100" iyz="0.00000" izz="0.00100"/>
      <origin rpy="0.00000 0.00000 0.00000" xyz="0.00000 0.00000 0.00000"/>
      <mass value="2.00000"/>
    </inertial>
    <visual name="Cilindro_i3">
      <origin rpy="-0.00000 -0.00000 0.00000" xyz="0.00000 0.00000 0.00000"/>
      <material name="Material.008"/>
      <geometry>
        <mesh filename="../meshes/dae/Cilindro.003.dae" scale="0.25000 0.25000 0.27500"/>
      </geometry>
    </visual>
  </link>
  <link name="Cilindro_link">
    <collision name="Cilindro_collision">
      <origin rpy="0.00000 -0.00000 0.00000" xyz="-0.00000 -0.00000 0.00000"/>
      <geometry>
        <mesh filename="../meshes/dae/Cilindro.008.dae" scale="0.15000 0.15000 0.10000"/>
      </geometry>
    </collision>
    <inertial>
      <inertia ixx="0.00223" ixy="0.00000" ixz="-0.00000" iyy="0.00223" iyz="0.00000" izz="0.00279"/>
      <origin rpy="0.00000 0.00000 0.00000" xyz="-0.00000 0.00000 -0.00000"/>
      <mass value="0.25000"/>
    </inertial>
    <visual name="Cilindro">
      <origin rpy="0.00000 0.00000 0.00000" xyz="-0.00000 -0.00000 0.00000"/>
      <material name="Material"/>
      <geometry>
        <mesh filename="../meshes/dae/Cilindro.008.dae" scale="0.15000 0.15000 0.10000"/>
      </geometry>
    </visual>
  </link>
  <link name="Cilindro_verti_1_link">
    <inertial>
      <inertia ixx="0.08892" ixy="0.00000" ixz="-0.00000" iyy="0.08892" iyz="-0.00000" izz="0.01118"/>
      <origin rpy="0.00000 0.00000 0.00000" xyz="-0.00000 0.00000 0.00000"/>
      <mass value="1.00000"/>
    </inertial>
    <visual name="Cilindro_verti_1">
      <origin rpy="0.00000 0.00000 0.00000" xyz="-0.00000 -0.00000 -0.00000"/>
      <material name="Material.001"/>
      <geometry>
        <mesh filename="../meshes/dae/Cilindro.007.dae" scale="0.15000 0.15000 0.50000"/>
      </geometry>
    </visual>
  </link>
  <link name="Cilindro_verti_3_link">
    <collision name="Cilindro_verti_3_collision">
      <origin rpy="0.00000 0.00000 0.00000" xyz="0.00000 -0.00000 -0.00000"/>
      <geometry>
        <mesh filename="../meshes/dae/Cilindro.009.dae" scale="0.15000 0.15000 0.20000"/>
      </geometry>
    </collision>
    <inertial>
      <inertia ixx="0.00946" ixy="0.00000" ixz="-0.00000" iyy="0.00946" iyz="0.00000" izz="0.00559"/>
      <origin rpy="0.00000 0.00000 0.00000" xyz="-0.00000 0.00000 -0.00000"/>
      <mass value="0.50000"/>
    </inertial>
    <visual name="Cilindro_verti_3">
      <origin rpy="0.00000 0.00000 0.00000" xyz="0.00000 -0.00000 -0.00000"/>
      <material name="Material"/>
      <geometry>
        <mesh filename="../meshes/dae/Cilindro.009.dae" scale="0.15000 0.15000 0.20000"/>
      </geometry>
    </visual>
  </link>
  <link name="Cilindro_verti_4_link">
    <collision name="Cilindro_verti_4_collision">
      <origin rpy="0.00000 0.00000 0.00000" xyz="-0.00000 -0.00000 -0.00000"/>
      <geometry>
        <mesh filename="../meshes/dae/Cilindro.010.dae" scale="0.15000 0.15000 0.20000"/>
      </geometry>
    </collision>
    <inertial>
      <inertia ixx="0.00946" ixy="0.00000" ixz="-0.00000" iyy="0.00946" iyz="0.00000" izz="0.00559"/>
      <origin rpy="0.00000 0.00000 0.00000" xyz="-0.00000 -0.00000 -0.00000"/>
      <mass value="0.50000"/>
    </inertial>
    <visual name="Cilindro_verti_4">
      <origin rpy="0.00000 0.00000 0.00000" xyz="0.00000 -0.00000 -0.00000"/>
      <material name="Material"/>
      <geometry>
        <mesh filename="../meshes/dae/Cilindro.010.dae" scale="0.15000 0.15000 0.20000"/>
      </geometry>
    </visual>
  </link>
  <link name="Cilindro_verti_5_link">
    <collision name="Cilindro_verti_5_collision">
      <origin rpy="0.00000 0.00000 0.00000" xyz="-0.00000 0.01000 -0.00000"/>
      <geometry>
        <mesh filename="../meshes/dae/Cilindro.011.dae" scale="0.10000 0.10000 1.50000"/>
      </geometry>
    </collision>
    <inertial>
      <inertia ixx="1.12873" ixy="-0.00000" ixz="0.00000" iyy="1.12873" iyz="0.00000" izz="0.00745"/>
      <origin rpy="0.00000 0.00000 0.00000" xyz="0.00000 0.01000 0.00000"/>
      <mass value="1.50000"/>
    </inertial>
    <visual name="Cilindro_verti_5">
      <origin rpy="0.00000 0.00000 0.00000" xyz="0.00000 0.01000 -0.00000"/>
      <material name="Material.001"/>
      <geometry>
        <mesh filename="../meshes/dae/Cilindro.011.dae" scale="0.10000 0.10000 1.50000"/>
      </geometry>
    </visual>
  </link>
  <link name="Cubo_d1_link">
    <collision name="Dubo_d1_collision">
      <origin rpy="-0.00000 0.00000 0.00000" xyz="-0.00000 -0.00000 -0.00000"/>
      <geometry>
        <box size="0.10000 0.10000 1.30000"/>
      </geometry>
    </collision>
    <inertial>
      <inertia ixx="0.00100" ixy="0.00000" ixz="0.00000" iyy="0.00100" iyz="0.00000" izz="0.00100"/>
      <origin rpy="0.00000 0.00000 0.00000" xyz="0.00000 -0.00000 -0.00000"/>
      <mass value="2.00000"/>
    </inertial>
    <visual name="Dubo_d1">
      <origin rpy="-0.00000 0.00000 0.00000" xyz="0.00000 0.00000 -0.00000"/>
      <geometry>
        <mesh filename="../meshes/dae/Cubo.005.dae" scale="0.05000 0.05000 0.65000"/>
      </geometry>
    </visual>
  </link>
  <link name="Cubo_d2_link">
    <collision name="Cubo_d3_collision">
      <origin rpy="0.00000 0.00000 0.00000" xyz="0.00000 0.00000 -0.00000"/>
      <geometry>
        <box size="0.10000 0.10000 1.10000"/>
      </geometry>
    </collision>
    <inertial>
      <inertia ixx="0.00100" ixy="0.00000" ixz="0.00000" iyy="0.00100" iyz="0.00000" izz="0.00100"/>
      <origin rpy="0.00000 0.00000 0.00000" xyz="-0.00000 0.00000 0.00000"/>
      <mass value="2.00000"/>
    </inertial>
    <visual name="Cubo_d3">
      <origin rpy="0.00000 0.00000 0.00000" xyz="0.00000 0.00000 -0.00000"/>
      <geometry>
        <mesh filename="../meshes/dae/Cubo.004.dae" scale="0.05000 0.05000 0.55000"/>
      </geometry>
    </visual>
  </link>
  <link name="Cubo_d3_link">
    <collision name="Cubo_d2_collision">
      <origin rpy="0.00000 0.00000 0.00000" xyz="-0.00000 0.00000 -0.00000"/>
      <geometry>
        <box size="0.10000 0.10000 1.30000"/>
      </geometry>
    </collision>
    <inertial>
      <inertia ixx="0.00100" ixy="0.00000" ixz="0.00000" iyy="0.00100" iyz="0.00000" izz="0.00100"/>
      <origin rpy="0.00000 0.00000 0.00000" xyz="0.00000 0.00000 -0.00000"/>
      <mass value="2.00000"/>
    </inertial>
    <visual name="Cubo_d2">
      <origin rpy="0.00000 0.00000 0.00000" xyz="0.00000 -0.00000 -0.00000"/>
      <geometry>
        <mesh filename="../meshes/dae/Cubo.003.dae" scale="0.05000 0.05000 0.65000"/>
      </geometry>
    </visual>
  </link>
  <link name="Cubo_i1_link">
    <collision name="Cubo_i1_collision">
      <origin rpy="-0.00000 0.00000 0.00000" xyz="0.00000 -0.00000 -0.00000"/>
      <geometry>
        <box size="0.10000 0.10000 1.30000"/>
      </geometry>
    </collision>
    <visual name="Cubo_i1">
      <origin rpy="-0.00000 0.00000 0.00000" xyz="0.00000 0.00000 -0.00000"/>
      <geometry>
        <mesh filename="../meshes/dae/Cubo.dae" scale="0.05000 0.05000 0.65000"/>
      </geometry>
    </visual>
  </link>
  <link name="Cubo_i2_link">
    <collision name="Cubo_i2_collision">
      <origin rpy="-0.00000 0.00000 0.00000" xyz="-0.00000 0.00000 -0.00000"/>
      <geometry>
        <mesh filename="../meshes/dae/Cubo.001.dae" scale="0.05000 0.05000 0.65000"/>
      </geometry>
    </collision>
    <visual name="Cubo_i2">
      <origin rpy="0.00000 0.00000 0.00000" xyz="0.00000 -0.00000 -0.00000"/>
      <geometry>
        <mesh filename="../meshes/dae/Cubo.001.dae" scale="0.05000 0.05000 0.65000"/>
      </geometry>
    </visual>
  </link>
  <link name="Cubo_i3_link">
    <collision name="Cubo_i3_collision">
      <origin rpy="0.00000 0.00000 0.00000" xyz="-0.00000 0.00000 -0.00000"/>
      <geometry>
        <mesh filename="../meshes/dae/Cubo.002.dae" scale="0.05000 0.05000 0.55000"/>
      </geometry>
    </collision>
    <visual name="Cubo_i3">
      <origin rpy="0.00000 0.00000 0.00000" xyz="-0.00000 0.00000 -0.00000"/>
      <geometry>
        <mesh filename="../meshes/dae/Cubo.002.dae" scale="0.05000 0.05000 0.55000"/>
      </geometry>
    </visual>
  </link>
  <link name="Rueda_D1_link">
    <collision name="Rueda_D1_collision">
      <origin rpy="0.00000 0.00000 -0.00000" xyz="-0.00000 0.00000 0.00000"/>
      <geometry>
        <mesh filename="../meshes/dae/Rosca.dae" scale="0.40000 0.40000 1.00000"/>
      </geometry>
    </collision>
    <visual name="Rueda_D1">
      <origin rpy="-0.00000 -0.00000 0.00000" xyz="-0.00000 0.00000 0.00000"/>
      <material name="Material.007"/>
      <geometry>
        <mesh filename="../meshes/dae/Rosca.dae" scale="0.40000 0.40000 1.00000"/>
      </geometry>
    </visual>
  </link>
  <link name="Rueda_D2_link">
    <collision name="Rueda_D2_collision">
      <origin rpy="0.00000 0.00000 0.00000" xyz="0.00000 -0.00000 0.00000"/>
      <geometry>
        <mesh filename="../meshes/dae/Rosca.005.dae" scale="0.40000 0.40000 1.00000"/>
      </geometry>
    </collision>
    <visual name="Rueda_D2">
      <origin rpy="-0.00000 -0.00000 0.00000" xyz="-0.00000 -0.00000 -0.00000"/>
      <material name="Material.007"/>
      <geometry>
        <mesh filename="../meshes/dae/Rosca.005.dae" scale="0.40000 0.40000 1.00000"/>
      </geometry>
    </visual>
  </link>
  <link name="Rueda_D3_link">
    <collision name="Rueda_D3_collision">
      <origin rpy="0.00000 0.00000 0.00000" xyz="0.00000 0.00000 0.00000"/>
      <geometry>
        <mesh filename="../meshes/dae/Rosca.001.dae" scale="0.40000 0.40000 1.00000"/>
      </geometry>
    </collision>
    <visual name="Rueda_D3">
      <origin rpy="0.00000 0.00000 0.00000" xyz="0.00000 0.00000 0.00000"/>
      <material name="Material.007"/>
      <geometry>
        <mesh filename="../meshes/dae/Rosca.001.dae" scale="0.40000 0.40000 1.00000"/>
      </geometry>
    </visual>
  </link>
  <link name="Rueda_I1_link">
    <collision name="Rueda_I1_collision">
      <origin rpy="3.14159 0.00000 -3.14159" xyz="0.00000 0.00000 0.00000"/>
      <geometry>
        <mesh filename="../meshes/dae/Rosca.004.dae" scale="0.40000 0.40000 1.00000"/>
      </geometry>
    </collision>
    <visual name="Rueda_I1">
      <origin rpy="3.14159 0.00000 -3.14159" xyz="0.00000 0.00000 0.00000"/>
      <material name="Material.007"/>
      <geometry>
        <mesh filename="../meshes/dae/Rosca.004.dae" scale="0.40000 0.40000 1.00000"/>
      </geometry>
    </visual>
  </link>
  <link name="Rueda_I2_link">
    <collision name="Rueda_I2_collision">
      <origin rpy="3.14159 0.00000 -3.14159" xyz="-0.00000 -0.00000 0.00000"/>
      <geometry>
        <mesh filename="../meshes/dae/Rosca.003.dae" scale="0.40000 0.40000 1.00000"/>
      </geometry>
    </collision>
    <visual name="Rueda_I2">
      <origin rpy="3.14159 0.00000 3.14159" xyz="0.00000 0.00000 -0.00000"/>
      <material name="Material.007"/>
      <geometry>
        <mesh filename="../meshes/dae/Rosca.003.dae" scale="0.40000 0.40000 1.00000"/>
      </geometry>
    </visual>
  </link>
  <link name="Rueda_i3_link">
    <collision name="Rueda_i3_collision">
      <origin rpy="3.14159 -0.00000 3.14159" xyz="-0.00000 0.00000 0.00000"/>
      <geometry>
        <mesh filename="../meshes/dae/Rosca.002.dae" scale="0.40000 0.40000 1.00000"/>
      </geometry>
    </collision>
    <visual name="Rueda_i3">
      <origin rpy="3.14159 0.00000 3.14159" xyz="0.00000 0.00000 0.00000"/>
      <material name="Material.007"/>
      <geometry>
        <mesh filename="../meshes/dae/Rosca.002.dae" scale="0.40000 0.40000 1.00000"/>
      </geometry>
    </visual>
  </link>
  <link name="Sensor_link"/>
  <link name="base_b_link">
    <collision name="base_b_collision">
      <origin rpy="0.00000 -1.57080 0.00000" xyz="0.00000 -0.00000 0.00000"/>
      <geometry>
        <mesh filename="../meshes/dae/Cilindro.dae" scale="0.35000 0.35000 0.05000"/>
      </geometry>
    </collision>
    <inertial>
      <inertia ixx="0.03126" ixy="0.00000" ixz="0.00000" iyy="0.03126" iyz="0.00000" izz="0.06086"/>
      <origin rpy="0.00000 0.00000 0.00000" xyz="0.00000 -0.00000 0.00000"/>
      <mass value="1.00000"/>
    </inertial>
    <visual name="base_b">
      <origin rpy="0.00000 -1.57080 0.00000" xyz="0.00000 -0.00000 0.00000"/>
      <material name="Material.001"/>
      <geometry>
        <mesh filename="../meshes/dae/Cilindro.dae" scale="0.35000 0.35000 0.05000"/>
      </geometry>
    </visual>
  </link>
  <link name="base_footprint"/>
  <link name="base_link">
    <collision name="Cube_collision">
      <origin rpy="0.00000 0.00000 0.00000" xyz="0.00000 0.00000 0.00000"/>
      <geometry>
        <box size="1.20000 2.50000 1.00000"/>
      </geometry>
    </collision>
    <inertial>
      <inertia ixx="18.12500" ixy="-0.00000" ixz="0.00000" iyy="6.10000" iyz="0.00000" izz="19.22500"/>
      <origin rpy="0.00000 0.00000 0.00000" xyz="0.00000 0.00000 0.00000"/>
      <mass value="30.00000"/>
    </inertial>
    <visual name="Cube">
      <origin rpy="0.00000 0.00000 0.00000" xyz="0.00000 0.00000 0.00000"/>
      <material name="Material.002"/>
      <geometry>
        <mesh filename="../meshes/dae/Cube.dae" scale="0.60000 1.25000 0.50000"/>
      </geometry>
    </visual>
  </link>
  <link name="grip_d_link">
    <collision name="grip_d_collision">
      <origin rpy="0.00000 -0.00000 0.00000" xyz="0.00000 0.00000 0.00000"/>
      <geometry>
        <box size="0.50000 0.40000 0.10000"/>
      </geometry>
    </collision>
    <inertial>
      <inertia ixx="0.01708" ixy="0.00000" ixz="-0.00000" iyy="0.01083" iyz="0.00000" izz="0.00708"/>
      <origin rpy="0.00000 0.00000 0.00000" xyz="0.00000 -0.00000 0.00000"/>
      <mass value="0.50000"/>
    </inertial>
    <visual name="grip_d">
      <origin rpy="0.00000 0.00000 0.00000" xyz="0.00000 -0.00000 0.00000"/>
      <material name="Material.001"/>
      <geometry>
        <box size="0.50000 0.40000 0.10000"/>
      </geometry>
    </visual>
  </link>
  <link name="grip_i_link">
    <collision name="grip_i_collision">
      <origin rpy="3.14159 0.00000 3.14159" xyz="0.00000 0.00000 0.00000"/>
      <geometry>
        <box size="0.50000 0.40000 0.10000"/>
      </geometry>
    </collision>
    <inertial>
      <inertia ixx="0.01708" ixy="0.00000" ixz="0.00000" iyy="0.01083" iyz="0.00000" izz="0.00708"/>
      <origin rpy="0.00000 0.00000 0.00000" xyz="0.00000 -0.00000 0.00000"/>
      <mass value="0.50000"/>
    </inertial>
    <visual name="grip_i">
      <origin rpy="3.14159 0.00000 3.14159" xyz="-0.00000 -0.00000 -0.00000"/>
      <material name="Material.001"/>
      <geometry>
        <box size="0.50000 0.40000 0.10000"/>
      </geometry>
    </visual>
  </link>
  <link name="grip_link">
    <collision name="grip_collision">
      <origin rpy="0.00000 0.00000 0.00000" xyz="-0.00000 0.00000 0.00000"/>
      <geometry>
        <box size="0.90000 0.40000 0.10000"/>
      </geometry>
    </collision>
    <inertial>
      <inertia ixx="0.00708" ixy="0.00000" ixz="0.00000" iyy="0.03417" iyz="0.00000" izz="0.04042"/>
      <origin rpy="0.00000 0.00000 0.00000" xyz="-0.00000 0.00000 0.00000"/>
      <mass value="0.50000"/>
    </inertial>
    <visual name="grip">
      <origin rpy="0.00000 0.00000 0.00000" xyz="0.00000 -0.00000 0.00000"/>
      <material name="Material.001"/>
      <geometry>
        <box size="0.90000 0.40000 0.10000"/>
      </geometry>
    </visual>
  </link>
  <link name="horizontal1_link">
    <collision name="horizontal1_collision">
      <origin rpy="0.00000 0.00000 0.00000" xyz="0.00000 -0.00000 -0.00000"/>
      <geometry>
        <mesh filename="../meshes/dae/Cubo.020.dae" scale="0.15000 0.50000 0.10000"/>
      </geometry>
    </collision>
    <inertial>
      <inertia ixx="0.08667" ixy="0.00000" ixz="0.00000" iyy="0.01083" iyz="0.00000" izz="0.09083"/>
      <origin rpy="0.00000 0.00000 0.00000" xyz="0.00000 -0.00000 -0.00000"/>
      <mass value="1.00000"/>
    </inertial>
    <visual name="horizontal1">
      <origin rpy="0.00000 0.00000 0.00000" xyz="0.00000 -0.00000 -0.00000"/>
      <material name="Material.001"/>
      <geometry>
        <mesh filename="../meshes/dae/Cubo.020.dae" scale="0.15000 0.50000 0.10000"/>
      </geometry>
    </visual>
  </link>
  <link name="horizontal2_link">
    <collision name="horizontal2_collision">
      <origin rpy="0.00000 0.00000 0.00000" xyz="0.00000 0.00000 -0.00000"/>
      <geometry>
        <mesh filename="../meshes/dae/Cubo.021.dae" scale="0.15000 0.50000 0.10000"/>
      </geometry>
    </collision>
    <inertial>
      <inertia ixx="0.08667" ixy="0.00000" ixz="0.00000" iyy="0.01083" iyz="0.00000" izz="0.09083"/>
      <origin rpy="0.00000 0.00000 0.00000" xyz="-0.00000 0.00000 -0.00000"/>
      <mass value="1.00000"/>
    </inertial>
    <visual name="horizontal2">
      <origin rpy="0.00000 0.00000 0.00000" xyz="-0.00000 -0.00000 0.00000"/>
      <material name="Material.001"/>
      <geometry>
        <mesh filename="../meshes/dae/Cubo.021.dae" scale="0.15000 0.50000 0.10000"/>
      </geometry>
    </visual>
  </link>
  <link name="pared_d_link">
    <collision name="pared_d_collision">
      <origin rpy="-0.00000 1.57080 0.00000" xyz="-0.00000 -0.00000 0.00000"/>
      <geometry>
        <box size="0.05000 1.30000 0.50000"/>
      </geometry>
    </collision>
    <visual name="pared_d">
      <origin rpy="-0.00000 1.57080 0.00000" xyz="-0.00000 0.00000 -0.00000"/>
      <material name="Material"/>
      <geometry>
        <box size="0.05000 1.30000 0.50000"/>
      </geometry>
    </visual>
  </link>
  <link name="pared_delantera_link">
    <collision name="pared_delantera_collision">
      <origin rpy="1.92225 1.57080 1.92225" xyz="-0.00000 -0.00000 0.00000"/>
      <geometry>
        <box size="0.05000 1.10000 0.50000"/>
      </geometry>
    </collision>
    <visual name="pared_delantera">
      <origin rpy="1.92225 1.57080 1.92225" xyz="-0.00000 -0.00000 0.00000"/>
      <material name="Material"/>
      <geometry>
        <box size="0.05000 1.10000 0.50000"/>
      </geometry>
    </visual>
  </link>
  <link name="pared_i_link">
    <collision name="pared_i_collision">
      <origin rpy="0.00000 -1.57080 0.00000" xyz="0.00000 -0.00000 0.00000"/>
      <geometry>
        <box size="0.05000 1.30000 0.50000"/>
      </geometry>
    </collision>
    <visual name="pared_i">
      <origin rpy="0.00000 -1.57080 0.00000" xyz="-0.00000 -0.00000 -0.00000"/>
      <material name="Material"/>
      <geometry>
        <box size="0.05000 1.30000 0.50000"/>
      </geometry>
    </visual>
  </link>
  <link name="pared_trasera_link">
    <collision name="pared_trasera_collision">
      <origin rpy="-1.57080 -1.57080 1.57080" xyz="0.00000 -0.00000 0.00000"/>
      <geometry>
        <box size="0.06000 1.10000 0.50000"/>
      </geometry>
    </collision>
    <visual name="pared_trasera">
      <origin rpy="-1.57080 -1.57080 1.57080" xyz="0.00000 0.00000 -0.00000"/>
      <material name="Material"/>
      <geometry>
        <box size="0.06000 1.10000 0.50000"/>
      </geometry>
    </visual>
  </link>
  <material name="Material">
    <color rgba="0.14118 0.13333 0.13725 1.00000"/>
  </material>
  <material name="Material.001">
    <color rgba="0.37255 0.37255 0.37255 1.00000"/>
  </material>
  <material name="Material.002">
    <color rgba="0.18824 0.00000 0.00392 1.00000"/>
  </material>
  <material name="Material.007">
    <color rgba="0.00000 0.00000 0.00000 1.00000"/>
  </material>
  <material name="Material.008">
    <color rgba="0.23922 0.23922 0.23922 1.00000"/>
  </material>
</robot>