<?xml version="1.0"?>
<!-- created with Phobos 1.0.1 "Capricious Choutengan" -->
<robot name="rover" xmlns:xacro="http://wiki.ros.org/xacro">
  
  <xacro:macro name="scara" params="parent_link">
  
    <!-- JOINT BRAZO -->
    <joint name="00_base_b_link_joint" type="fixed">
      <origin rpy="-0.00000 1.57080 0.00000" xyz="0.00000 0.70000 0.55000"/>
      <parent link="${parent_link}"/>
      <child link="base_b_link"/>
    </joint>
    <joint name="01_Cilindro_verti_1_link_joint" type="fixed">
      <origin rpy="0.00000 -1.57080 0.00000" xyz="-0.55000 0.00000 0.00000"/>
      <parent link="base_b_link"/>
      <child link="Cilindro_verti_1_link"/>
    </joint>

    <joint name="03_horizontal1_link_joint" type="fixed">
      <origin rpy="0.00000 0.00000 0.00000" xyz="0.00000 0.50000 -0.00000"/>
      <parent link="Cilindro_link"/>
      <child link="horizontal1_link"/>
    </joint>
    <joint name="04_Cilindro_verti_3_link_joint" type="revolute">
      <limit lower="-2.15000" upper="2.15000" effort="25.00000" velocity="0.00000"/>
      <origin rpy="0.00000 0.00000 0.00000" xyz="0.00000 0.50000 0.10000"/>
      <parent link="horizontal1_link"/>
      <child link="Cilindro_verti_3_link"/>
      <axis xyz="0.00000 0.00000 1.00000"/>
    </joint>
    <joint name="05_horizontal2_link_joint" type="fixed">
      <origin rpy="0.00000 0.00000 0.00000" xyz="-0.00000 0.50000 0.10000"/>
      <parent link="Cilindro_verti_3_link"/>
      <child link="horizontal2_link"/>
    </joint>
    <joint name="06_Cilindro_verti_4_link_joint" type="fixed">
      <origin rpy="0.00000 0.00000 0.00000" xyz="0.00000 0.50000 0.10000"/>
      <parent link="horizontal2_link"/>
      <child link="Cilindro_verti_4_link"/>
    </joint>

    <joint name="02_Cilindro_link_joint" type="revolute">
      <limit lower="-6.28000" upper="6.28000" effort="25.00000" velocity="0.00000"/>
      <origin rpy="0.00000 0.00000 0.00000" xyz="0.00000 0.00000 0.60000"/>
      <parent link="Cilindro_verti_1_link"/>
      <child link="Cilindro_link"/>
      <axis xyz="0.00000 0.00000 1.00000"/>
    </joint>

    <joint name="07_Cilindro_verti_5_link_joint" type="prismatic">
      <limit lower="-2.00000" upper="2.50000" effort="25.00000" velocity="0.00000"/>
      <origin rpy="0.00000 0.00000 0.00000" xyz="0.00000 -0.01000 -1.00000"/>
      <parent link="Cilindro_verti_4_link"/>
      <child link="Cilindro_verti_5_link"/>
      <axis xyz="0.00000 0.00000 1.00000"/>
    </joint>

<!-- LINK SCARA -->
    <link name="base_b_link">
      <collision name="base_b_collision">
        <origin rpy="0.00000 -1.57080 0.00000" xyz="0.00000 -0.00000 0.00000"/>
        <geometry>
          <mesh filename="file://$(find rover_description)/meshes/dae/Cilindro.dae" scale="0.35000 0.35000 0.05000"/>
        </geometry>
      </collision>
      <inertial>
        <inertia ixx="0.03126" ixy="0.00000" ixz="0.00000" iyy="0.03126" iyz="0.00000" izz="0.06086"/>
        <origin rpy="0.00000 0.00000 0.00000" xyz="0.00000 -0.00000 0.00000"/>
        <mass value="1.00000"/>
      </inertial>
      <visual name="base_b">
        <origin rpy="0.00000 -1.57080 0.00000" xyz="0.00000 -0.00000 -0.00000"/>
        <material name="Material.001"/>
        <geometry>
          <mesh filename="file://$(find rover_description)/meshes/dae/Cilindro.dae" scale="0.35000 0.35000 0.05000"/>
        </geometry>
      </visual>
    </link>

    <link name="horizontal1_link">
      <collision name="horizontal1_collision">
        <origin rpy="0.00000 0.00000 0.00000" xyz="0.00000 -0.00000 0.00000"/>
        <geometry>
          <mesh filename="file://$(find rover_description)/meshes/dae/Cubo.020.dae" scale="0.15000 0.50000 0.10000"/>
        </geometry>
      </collision>
      <inertial>
        <inertia ixx="0.08667" ixy="0.00000" ixz="0.00000" iyy="0.01083" iyz="0.00000" izz="0.09083"/>
        <origin rpy="0.00000 0.00000 0.00000" xyz="0.00000 -0.00000 0.00000"/>
        <mass value="1.00000"/>
      </inertial>
      <visual name="horizontal1">
        <origin rpy="0.00000 0.00000 0.00000" xyz="0.00000 -0.00000 -0.00000"/>
        <material name="Material.001"/>
        <geometry>
          <mesh filename="file://$(find rover_description)/meshes/dae/Cubo.020.dae" scale="0.15000 0.50000 0.10000"/>
        </geometry>
      </visual>
    </link>
    <link name="horizontal2_link">
      <collision name="horizontal2_collision">
        <origin rpy="0.00000 0.00000 0.00000" xyz="0.00000 -0.00000 -0.00000"/>
        <geometry>
          <mesh filename="file://$(find rover_description)/meshes/dae/Cubo.021.dae" scale="0.15000 0.50000 0.10000"/>
        </geometry>
      </collision>
      <inertial>
        <inertia ixx="0.08667" ixy="0.00000" ixz="0.00000" iyy="0.01083" iyz="0.00000" izz="0.09083"/>
        <origin rpy="0.00000 0.00000 0.00000" xyz="0.00000 0.00000 -0.00000"/>
        <mass value="1.00000"/>
      </inertial>
      <visual name="horizontal2">
        <origin rpy="0.00000 0.00000 0.00000" xyz="0.00000 -0.00000 -0.00000"/>
        <material name="Material.001"/>
        <geometry>
          <mesh filename="file://$(find rover_description)/meshes/dae/Cubo.021.dae" scale="0.15000 0.50000 0.10000"/>
        </geometry>
      </visual>
    </link>


    <link name="Cilindro_verti_1_link">
      <inertial>
        <inertia ixx="0.08892" ixy="0.00000" ixz="-0.00000" iyy="0.08892" iyz="-0.00000" izz="0.01118"/>
        <origin rpy="0.00000 0.00000 0.00000" xyz="-0.00000 0.00000 0.00000"/>
        <mass value="1.00000"/>
      </inertial>
      <visual name="Cilindro_verti_1">
        <origin rpy="0.00000 0.00000 0.00000" xyz="0.00000 0.00000 0.00000"/>
        <material name="Material.001"/>
        <geometry>
          <mesh filename="file://$(find rover_description)/meshes/dae/Cilindro.007.dae" scale="0.15000 0.15000 0.50000"/>
        </geometry>
      </visual>
    </link>
    <link name="Cilindro_verti_3_link">
      <collision name="Cilindro_verti_3_collision">
        <origin rpy="0.00000 0.00000 0.00000" xyz="0.00000 -0.00000 -0.00000"/>
        <geometry>
          <mesh filename="file://$(find rover_description)/meshes/dae/Cilindro.009.dae" scale="0.15000 0.15000 0.20000"/>
        </geometry>
      </collision>
      <inertial>
        <inertia ixx="0.00946" ixy="0.00000" ixz="-0.00000" iyy="0.00946" iyz="0.00000" izz="0.00559"/>
        <origin rpy="0.00000 0.00000 0.00000" xyz="-0.00000 -0.00000 -0.00000"/>
        <mass value="0.50000"/>
      </inertial>
      <visual name="Cilindro_verti_3">
        <origin rpy="0.00000 0.00000 0.00000" xyz="0.00000 -0.00000 -0.00000"/>
        <material name="Material"/>
        <geometry>
          <mesh filename="file://$(find rover_description)/meshes/dae/Cilindro.009.dae" scale="0.15000 0.15000 0.20000"/>
        </geometry>
      </visual>
    </link>
    <link name="Cilindro_verti_4_link">
      <collision name="Cilindro_verti_4_collision">
        <origin rpy="0.00000 0.00000 0.00000" xyz="0.00000 -0.00000 0.00000"/>
        <geometry>
          <mesh filename="file://$(find rover_description)/meshes/dae/Cilindro.010.dae" scale="0.15000 0.15000 0.20000"/>
        </geometry>
      </collision>
      <inertial>
        <inertia ixx="0.00946" ixy="0.00000" ixz="-0.00000" iyy="0.00946" iyz="0.00000" izz="0.00559"/>
        <origin rpy="0.00000 0.00000 0.00000" xyz="-0.00000 -0.00000 -0.00000"/>
        <mass value="0.50000"/>
      </inertial>
      <visual name="Cilindro_verti_4">
        <origin rpy="0.00000 0.00000 0.00000" xyz="0.00000 -0.00000 0.00000"/>
        <material name="Material"/>
        <geometry>
          <mesh filename="file://$(find rover_description)/meshes/dae/Cilindro.010.dae" scale="0.15000 0.15000 0.20000"/>
        </geometry>
      </visual>
    </link>
    <link name="Cilindro_verti_5_link">
      <collision name="Cilindro_verti_5_collision">
        <origin rpy="0.00000 0.00000 0.00000" xyz="0.00000 0.01000 0.00000"/>
        <geometry>
          <mesh filename="file://$(find rover_description)/meshes/dae/Cilindro.011.dae" scale="0.10000 0.10000 1.50000"/>
        </geometry>
      </collision>
      <inertial>
        <inertia ixx="1.12873" ixy="-0.00000" ixz="0.00000" iyy="1.12873" iyz="0.00000" izz="0.00745"/>
        <origin rpy="0.00000 0.00000 0.00000" xyz="0.00000 0.01000 -0.00000"/>
        <mass value="1.50000"/>
      </inertial>
      <visual name="Cilindro_verti_5">
        <origin rpy="0.00000 0.00000 0.00000" xyz="0.00000 0.01000 -0.00000"/>
        <material name="Material.001"/>
        <geometry>
          <mesh filename="file://$(find rover_description)/meshes/dae/Cilindro.011.dae" scale="0.10000 0.10000 1.50000"/>
        </geometry>
      </visual>
    </link>

  </xacro:macro>
</robot>
